Workbook

Sheet Abilità
B1: Punti Abilità Tot: | D1: =SUM(Generali!$O$14:$O$31) -> 24 | E1: Punti Abilità Disp: | G1: =D1 -(SUM(T4:T33, AC4:AC31)) -> 0
B3: TALENTI | I3: TRATTI RAZZIALI | O3: Nome abilità | P3: Classe | Q3: CI (classe incrociata) | R3: Caratt. | S3: Mod. | T3: Gradi | U3: Vari | V3: TOT | X3: Nome abilità | Y3: Classe | Z3: CI (classe incrociata) | AA3: Caratt. | AB3: Mod. | AC3: Gradi | AD3: Vari | AE3: TOT
B4: talento | F4: manuale | G4: livello | I4: difetto: rinunciato al famiglio per 1 talento in più Sangue Caldo Fiato Corto | O4: Acrobazia | R4: DES | S4: =Generali!X7 -> 3 | V4: =ROUNDDOWN(SUM(S4,U4,IF(P4<>"",T4,ROUNDDOWN(T4/2,0))),0)+Equip!Y5+Equip!X13+IF(AC24>4,2,0)-Generali!$AR$7 -> 3 | X4: Falsificare | AA4: INT● | AB4: =Generali!$X$11 -> 4 | AE4: =ROUNDDOWN(SUM(AB4,AD4,IF(Y4<>"",AC4,ROUNDDOWN(AC4/2,0))),0)-Generali!AR7 -> 4
B5: Mago di collegio (P. arcanista p. 181) | G5: 1 Mago | O5: Addestrare animali | R5: CAR | S5: =Generali!X15 -> 2 | V5: =ROUNDDOWN(SUM(S5,U5,IF(P5<>"",T5,ROUNDDOWN(T5/2,0))),0)-Generali!$AR$7 -> 2 | X5: Guarire | AA5: SAG● | AB5: =Generali!X13 -> 2 | AE5: =ROUNDDOWN(SUM(AB5,AD5,IF(Y5<>"",AC5,ROUNDDOWN(AC5/2,0))),0)-Generali!AR7 -> 2
B6: Evocazione Rapida | G6: 1 Mago | O6: Artigianato 1 | P6: x | R6: INT● | S6: =Generali!$X$11 -> 4 | V6: =ROUNDDOWN(SUM(S6,U6,IF(P6<>"",T6,ROUNDDOWN(T6/2,0))),0)-Generali!$AR$7 -> 4 | X6: Intimidire | AA6: CAR● | AB6: =Generali!X15 -> 2 | AE6: =ROUNDDOWN(SUM(AB6,AD6,IF(Y6<>"",AC6,ROUNDDOWN(AC6/2,0))),0)+IF(AC22>4,2,0)-Generali!AR7 -> 2
B7: Aumentare Evocazione | G7: 1 Mago | O7: Artigianato 2 | R7: INT● | S7: =Generali!$X$11 -> 4 | V7: =ROUNDDOWN(SUM(S7,U7,IF(P7<>"",T7,ROUNDDOWN(T7/2,0))),0)-Generali!$AR$7 -> 4 | X7: Intrattenere danza | AA7: CAR● | AB7: =Generali!X15 -> 2 | AE7: =ROUNDDOWN(SUM(AB7,AD7,IF(Y7<>"",AC7,ROUNDDOWN(AC7/2,0))),0)-Generali!AR7 -> 2
O8: Artigianato 3 | R8: INT● | S8: =Generali!$X$11 -> 4 | V8: =ROUNDDOWN(SUM(S8,U8,IF(P8<>"",T8,ROUNDDOWN(T8/2,0))),0)-Generali!$AR$7 -> 4 | X8: Intrattenere 2 | AA8: CAR● | AB8: =Generali!X15 -> 2 | AE8: =ROUNDDOWN(SUM(AB8,AD8,IF(Y8<>"",AC8,ROUNDDOWN(AC8/2,0))),0)-Generali!AR7 -> 2
O9: Artigianato 4 | R9: INT● | S9: =Generali!$X$11 -> 4 | V9: =ROUNDDOWN(SUM(S9,U9,IF(P9<>"",T9,ROUNDDOWN(T9/2,0))),0)-Generali!$AR$7 -> 4 | X9: Intrattenere 3 | AA9: CAR● | AB9: =Generali!X15 -> 2 | AE9: =ROUNDDOWN(SUM(AB9,AD9,IF(Y9<>"",AC9,ROUNDDOWN(AC9/2,0))),0)-Generali!AR7 -> 2
O10: Artigianato 5 | R10: INT● | S10: =Generali!$X$11 -> 4 | V10: =ROUNDDOWN(SUM(S10,U10,IF(P10<>"",T10,ROUNDDOWN(T10/2,0))),0)-Generali!$AR$7 -> 4 | X10: Intrattenere 4 | AA10: CAR● | AB10: =Generali!X15 -> 2 | AE10: =ROUNDDOWN(SUM(AB10,AD10,IF(Y10<>"",AC10,ROUNDDOWN(AC10/2,0))),0)-Generali!AR7 -> 2
O11: Artigianato 6 | R11: INT● | S11: =Generali!$X$11 -> 4 | V11: =ROUNDDOWN(SUM(S11,U11,IF(P11<>"",T11,ROUNDDOWN(T11/2,0))),0)-Generali!$AR$7 -> 4 | X11: Intrattenere 5 | AA11: CAR● | AB11: =Generali!X15 -> 2 | AE11: =ROUNDDOWN(SUM(AB11,AD11,IF(Y11<>"",AC11,ROUNDDOWN(AC11/2,0))),0)-Generali!AR7 -> 2
O12: Artista della fuga | R12: DES● | S12: =Generali!X7 -> 3 | V12: =ROUNDDOWN(SUM(S12,U12,IF(P12<>"",T12,ROUNDDOWN(T12/2,0))),0)+Equip!Y5+Equip!X13-Generali!AR7 -> 3 | X12: Intrattenere 6 | AA12: CAR● | AB12: =Generali!X15 -> 2 | AE12: =ROUNDDOWN(SUM(AB12,AD12,IF(Y12<>"",AC12,ROUNDDOWN(AC12/2,0))),0)-Generali!AR7 -> 2
O13: Ascoltare | R13: SAG | S13: =Generali!X13 -> 2 | U13: 2 | V13: =ROUNDDOWN(SUM(S13,U13,IF(P13<>"",T13,ROUNDDOWN(T13/2,0))),0)-Generali!AR7 -> 4 | X13: Muoversi Silenziosamente | AA13: DES● | AB13: =Generali!X7 -> 3 | AE13: =ROUNDDOWN(SUM(AB13,AD13,IF(Y13<>"",AC13,ROUNDDOWN(AC13/2,0))),0)+Equip!Y5+Equip!X13-Generali!AR7 -> 3
O14: Camuffare | R14: CAR● | S14: =Generali!X15 -> 2 | V14: =ROUNDDOWN(SUM(S14,U14,IF(P14<>"",T14,ROUNDDOWN(T14/2,0))),0)+IF(AC22>4,2,0)-Generali!AR7 -> 2 | X14: Nascondersi | AA14: DES● | AB14: =Generali!X7 -> 3 | AE14: =ROUNDDOWN(SUM(AB14,AD14,IF(Y14<>"",AC14,ROUNDDOWN(AC14/2,0))),0)+Equip!Y5+Equip!X13-Generali!AR7 -> 3
O15: Cavalcare | R15: DES● | S15: =Generali!X7 -> 3 | V15: =ROUNDDOWN(SUM(S15,U15,IF(P15<>"",T15,ROUNDDOWN(T15/2,0))),0)+IF(T5>4,2,0)-Generali!AR7 -> 3 | X15: Nuotare | AA15: FOR● | AB15: =Generali!X5 -> 1 | AE15: =ROUNDDOWN(SUM(AB15,AD15,IF(Y15<>"",AC15,ROUNDDOWN(AC15/2,0))),0)+((Equip!Y5+Equip!X13)*2)-Generali!AR7 -> 1
O16: Cercare | R16: INT● | S16: =Generali!$X$11 -> 4 | U16: 2 | V16: =ROUNDDOWN(SUM(S16,U16,IF(P16<>"",T16,ROUNDDOWN(T16/2,0))),0)-Generali!AR7 -> 6 | X16: Osservare | AA16: SAG | AB16: =Generali!X13 -> 2 | AD16: 2 | AE16: =ROUNDDOWN(SUM(AB16,AD16,IF(Y16<>"",AC16,ROUNDDOWN(AC16/2,0))),0)-Generali!AR7 -> 4
O17: Concentrazione | P17: x | R17: COS● | S17: =Generali!X9 -> 1 | T17: 3 | V17: =ROUNDDOWN(SUM(S17,U17,IF(P17<>"",T17,ROUNDDOWN(T17/2,0))),0)-Generali!AR7 -> 4 | X17: Parlare linguaggi | AA17: - | AE17: =ROUNDDOWN(SUM(AB17,AD17,IF(Y17<>"",AC17,ROUNDDOWN(AC17/2,0))),0) -> 0
O18: Conoscenze locali | P18: x | R18: INT | S18: =Generali!$X$11 -> 4 | T18: 1 | V18: =ROUNDDOWN(SUM(S18,U18,IF(P18<>"",T18,ROUNDDOWN(T18/2,0))),0)-Generali!AR7 -> 5 | X18: Percepire Intenzioni | AA18: SAG● | AB18: =Generali!X13 -> 2 | AE18: =ROUNDDOWN(SUM(AB18,AD18,IF(Y18<>"",AC18,ROUNDDOWN(AC18/2,0))),0)-Generali!AR7 -> 2
O19: Con. arcane | P19: x | R19: INT | S19: =Generali!$X$11 -> 4 | T19: 3 | V19: =ROUNDDOWN(SUM(S19,U19,IF(P19<>"",T19,ROUNDDOWN(T19/2,0))),0)-Generali!AR7 -> 7 | X19: Professione 1 | Y19: x | AA19: SAG | AB19: =Generali!X13 -> 2 | AE19: =ROUNDDOWN(SUM(AB19,AD19,IF(Y19<>"",AC19,ROUNDDOWN(AC19/2,0))),0)-Generali!AR7 -> 2
O20: Con. architettura | P20: x | R20: INT | S20: =Generali!$X$11 -> 4 | T20: 1 | V20: =ROUNDDOWN(SUM(S20,U20,IF(P20<>"",T20,ROUNDDOWN(T20/2,0))),0)-Generali!AR7 -> 5 | X20: Professione 2 | AA20: SAG | AB20: =Generali!X13 -> 2 | AE20: =ROUNDDOWN(SUM(AB20,AD20,IF(Y20<>"",AC20,ROUNDDOWN(AC20/2,0))),0)-Generali!AR7 -> 2
O21: Con. dungeon | P21: x | R21: INT | S21: =Generali!$X$11 -> 4 | T21: 1 | V21: =ROUNDDOWN(SUM(S21,U21,IF(P21<>"",T21,ROUNDDOWN(T21/2,0))),0)-Generali!AR7 -> 5 | X21: Raccogliere informazioni | AA21: CAR● | AB21: =Generali!X15 -> 2 | AE21: =ROUNDDOWN(SUM(AB21,AD21,IF(Y21<>"",AC21,ROUNDDOWN(AC21/2,0))),0)-Generali!AR7 -> 2
O22: Con. geografia | P22: x | R22: INT | S22: =Generali!$X$11 -> 4 | T22: 1 | V22: =ROUNDDOWN(SUM(S22,U22,IF(P22<>"",T22,ROUNDDOWN(T22/2,0))),0)-Generali!AR7 -> 5 | X22: Raggirare | AA22: CAR● | AB22: =Generali!X15 -> 2 | AE22: =ROUNDDOWN(SUM(AB22,AD22,IF(Y22<>"",AC22,ROUNDDOWN(AC22/2,0))),0)-Generali!AR7 -> 2
O23: Con. natura | P23: x | R23: INT | S23: =Generali!$X$11 -> 4 | T23: 1 | V23: =ROUNDDOWN(SUM(S23,U23,IF(P23<>"",T23,ROUNDDOWN(T23/2,0))),0)-Generali!AR7 -> 5 | X23: Rapidità di mano | AA23: DES | AB23: =Generali!X7 -> 3 | AE23: =ROUNDDOWN(SUM(AB23,AD23,IF(Y23<>"",AC23,ROUNDDOWN(AC23/2,0))),0)+Equip!Y5+Equip!X13+IF(AC22>4,2,0)-Generali!AR7 -> 3
O24: Con. nobiltà e regalità | P24: x | R24: INT | S24: =Generali!$X$11 -> 4 | T24: 2 | V24: =ROUNDDOWN(SUM(S24,U24,IF(P24<>"",T24,ROUNDDOWN(T24/2,0))),0)-Generali!AR7 -> 6 | X24: Saltare | AA24: FOR● | AB24: =Generali!X5 -> 1 | AE24: =ROUNDDOWN(SUM(AB24,AD24,IF(Y24<>"",AC24,ROUNDDOWN(AC24/2,0))),0)+Equip!Y5+Equip!X13+IF(T4>4,2,0)-Generali!AR7 -> 1
O25: Con. piani | P25: x | R25: INT | S25: =Generali!$X$11 -> 4 | T25: 2 | V25: =ROUNDDOWN(SUM(S25,U25,IF(P25<>"",T25,ROUNDDOWN(T25/2,0))),0)-Generali!AR7 -> 6 | X25: Sapienza magica | Y25: x | AA25: INT | AB25: =Generali!$X$11 -> 4 | AC25: 4 | AE25: =ROUNDDOWN(SUM(AB25,AD25,IF(Y25<>"",AC25,ROUNDDOWN(AC25/2,0))),0)+IF(AC30>4,2,0)-Generali!AR7 -> 8
O26: Con. religioni | P26: x | R26: INT | S26: =Generali!$X$11 -> 4 | T26: 1 | V26: =ROUNDDOWN(SUM(S26,U26,IF(P26<>"",T26,ROUNDDOWN(T26/2,0))),0)-Generali!AR7 -> 5 | X26: Scalare | AA26: FOR● | AB26: =Generali!X5 -> 1 | AE26: =ROUNDDOWN(SUM(AB26,AD26,IF(Y26<>"",AC26,ROUNDDOWN(AC26/2,0))),0)+Equip!Y5+Equip!X13+IF(AC29>4,2,0)-Generali!AR7 -> 1
O27: Con. storia | P27: x | R27: INT | S27: =Generali!$X$11 -> 4 | T27: 1 | V27: =ROUNDDOWN(SUM(S27,U27,IF(P27<>"",T27,ROUNDDOWN(T27/2,0))),0)-Generali!AR7 -> 5 | X27: Scassinare Serrature | AA27: DES | AB27: =Generali!X7 -> 3 | AE27: =ROUNDDOWN(SUM(AB27,AD27,IF(Y27<>"",AC27,ROUNDDOWN(AC27/2,0))),0)-Generali!AR7 -> 3
O28: Conoscenze 11 | P28: x | R28: INT | S28: =Generali!$X$11 -> 4 | V28: =ROUNDDOWN(SUM(S28,U28,IF(P28<>"",T28,ROUNDDOWN(T28/2,0))),0)-Generali!AR7 -> 4 | X28: Sopravvivenza | AA28: SAG● | AB28: =Generali!X13 -> 2 | AE28: =ROUNDDOWN(SUM(AB28,AD28,IF(Y28<>"",AC28,ROUNDDOWN(AC28/2,0))),0)-Generali!AR7 -> 2
O29: Conoscenze 12 | P29: x | R29: INT | S29: =Generali!$X$11 -> 4 | V29: =ROUNDDOWN(SUM(S29,U29,IF(P29<>"",T29,ROUNDDOWN(T29/2,0))),0)-Generali!AR7 -> 4 | X29: Utilizzare corde | AA29: DES | AB29: =Generali!X7 -> 3 | AE29: =ROUNDDOWN(SUM(AB29,AD29,IF(Y29<>"",AC29,ROUNDDOWN(AC29/2,0))),0)+IF(T12>4,2,0)-Generali!AR7 -> 3
O30: Decifrare Scritture | P30: x | R30: INT | S30: =Generali!$X$11 -> 4 | T30: 3 | V30: =ROUNDDOWN(SUM(S30,U30,IF(P30<>"",T30,ROUNDDOWN(T30/2,0))),0)-Generali!AR7 -> 7 | X30: Utilizzare oggetti magici | AA30: CAR | AB30: =Generali!X15 -> 2 | AE30: =ROUNDDOWN(SUM(AB30,AD30,IF(Y30<>"",AC30,ROUNDDOWN(AC30/2,0))),0)+IF(AC25>4,2,0)+IF(T30>4,2,0)-Generali!AR7 -> 2
O31: Diplomazia | R31: CAR● | S31: =Generali!X15 -> 2 | V31: =ROUNDDOWN(SUM(S31,U31,IF(P31<>"",T31,ROUNDDOWN(T31/2,0))),0)+IF(AC22>4,2,0)+IF(AC18>4,2,0)-Generali!AR7 -> 2 | X31: Valutare | AA31: INT● | AB31: =Generali!$X$11 -> 4 | AE31: =ROUNDDOWN(SUM(AB31,AD31,IF(Y31<>"",AC31,ROUNDDOWN(AC31/2,0))),0)-Generali!AR7 -> 4
O32: Disattivare Congegni | R32: INT | S32: =Generali!$X$11 -> 4 | V32: =ROUNDDOWN(SUM(S32,U32,IF(P32<>"",T32,ROUNDDOWN(T32/2,0))),0)-Generali!AR7 -> 4 | X32: Totale Punti Abilità | AC32: =SUM(T4:T33,AC4:AC31) -> 24 | AD32: =SUM(U4:U33,AD4:AD31) -> 6 | AE32: =Generali!Q12+3 -> 4
O33: Equilibrio | R33: DES● | S33: =Generali!X7 -> 3 | V33: =ROUNDDOWN(SUM(S33,U33,IF(P33<>"",T33,ROUNDDOWN(T33/2,0))),0)+Equip!Y5+Equip!X13+IF(T4>4,2,0)-Generali!AR7 -> 3 | X33: ● denota un'abilità che può essere usata senza addestramento
X34: * se presente penalità alla prova applicata. (Doppia per nuotare). Se abilità di classe, scrivere X

Sheet Generali
C2: DATI DEL PERSONAGGIO | U2: CARATTERISTICHE | AI2: PUNTI FERITA
C3: Nome del Personaggio: | G3: Kaelen Vaelen | U3: Valore | X3: Modif. | Y3: Buff&Debuff temporanei | AB3: Modificatori di condizione | AJ3: p. ferita totali | AN3: pf da talenti | AP3: pf attuali | AR3: rigen. | AT3: g. rapida
C4: Nome del Giocatore: | M4: Data Creazione: | AJ4: =SUM(K14:K31)+((X9)*SUM(G14:G31))+AN4-(AR7*5) -> 5 | AP4: 4
C5: Razza: | D5: Elfo del Sole | K5: Sesso: | L5: M | O5: Pelle: | P5: Dorata | U5: FOR | V5: 12 | X5: =IF(MOD(((V5+Y5+Z5)-10)/2, 1)<>0, ((V5+Y5+Z5)-10)/2-0.5, ((V5+Y5+Z5)-10)/2) -> 1
C6: Età: | D6: 115 | E6: Altezza: | F6: 0.10763889 | I6: Peso: | M6: Capelli: | P6: Occhi: Smeraldo | AR6: livelli negativi | AT6: danni non letali
C7: Allineamento: | E7: Legale Buono | M7: Taglia: | U7: DES | V7: 17 | X7: =IF(MOD(((V7+Y7+Z7)-10)/2, 1)<>0, ((V7+Y7+Z7)-10)/2-0.5, ((V7+Y7+Z7)-10)/2) -> 3 | AJ7: riduzione danno | AN7: resistenza incantesimi
C8: Archetipi:
U9: COS | V9: =15-2 -> 13 | X9: =IF(MOD(((V9+Y9+Z9)-10)/2, 1)<>0, ((V9+Y9+Z9)-10)/2-0.5, ((V9+Y9+Z9)-10)/2) -> 1
AN10: resistenze elementali
C11: CLASSI E PUNTI ESPERIENZA | U11: INT | V11: =17+2 -> 19 | X11: =IF(MOD(((V11+Y11+Z11)-10)/2, 1)<>0, ((V11+Y11+Z11)-10)/2-0.5, ((V11+Y11+Z11)-10)/2) -> 4
C12: Classe | G12: Livello classe | I12: dado vita | K12: punti ferita | M12: classe preferita | N12: formula punti abilità | O12: punti Abilità | P12: Livello totale | Q12: =SUM(G14:H31) -> 1
U13: SAG | V13: 15 | X13: =IF(MOD(((V13+Y13+Z13)-10)/2, 1)<>0, ((V13+Y13+Z13)-10)/2-0.5, ((V13+Y13+Z13)-10)/2) -> 2
B14: A | C14: Mago | G14: 1 | I14: d4 | K14: 4 | M14: Mago | N14: 2+INT | O14: =24 -> 24 | P14: Punti Esperienza | Q14: =100+175 -> 275
U15: CAR | V15: 15 | X15: =IF(MOD(((V15+Y15+Z15)-10)/2, 1)<>0, ((V15+Y15+Z15)-10)/2-0.5, ((V15+Y15+Z15)-10)/2) -> 2
B16: B | P16: P.E. livello successivo | Q16: =VLOOKUP(Q12+1, Utility!A2:B21, 2, FALSE) - Q14 -> 725
U17: =IF(AR7>0, "sottrarre " & Generali!AR7 & " dalle prove caratteristica", "Non hai livelli negativi") -> Non hai livelli negativi
B18: C | P18: Penalità P.E | U18: BONUS ATTACCO BASE | AK18: INIZIATIVA
U19: bonus attacco base classi | AL19: des | AN19: talenti | AP19: magia | AR19: altro
B20: D | P20: P.E. Stirpe | V20: A | W20: 0 | Y20: BAB | AA20: taglia | AC20: forza | AE20: tc in mischia | AL20: =X7 -> 3 | AM20: + | AO20: + | AQ20: + | AS20: = | AT20: =AL20+AN20+AP20+AR20 -> 3
V21: B | Y21: =SUM(W20:W30)-W31 -> 0 | Z21: + | AB21: + | AC21: =X5 -> 1 | AD21: = | AE21: =SUM(Y21,AA21,AC21)-AR7 -> 1
B22: E | V22: C | Y22: + | AC22: destrezza | AE22: tc a distanza
P23: P.A. | Q23: LINGUE | S23: ALFAB. | V23: D | Z23: taglia | AC23: =X7 -> 3 | AD23: = | AE23: =SUM(Y21,AA21,AC23)-AR7 -> 3
B24: F | Q24: Comune | V24: E | Y24: + | AJ24: =SUM(AL25,AN25,AP25,AR25,AT25,AR27,AP27,AN27,AL27,AT27)+W31 -> 13 | AN24: armat. | AP24: scudo | AR24: des | AT24: taglia
Q25: Elfico | V25: F | Y25: =X5 -> 1 | Z25: forza | AK25: = | AL25: 10 | AM25: + | AN25: =Equip!V5 | AO25: + | AP25: =Equip!V13 | AQ25: + | AR25: =IF(ISBLANK(Equip!X5), X7, IF(X7 > Equip!X5, Equip!X5, X7)) -> 3 | AS25: + | AU25: +
B26: G | Q26: Draconico | V26: G | Y26: + | AB26: penalità combattere con due armi | AL26: naturale | AN26: deviazione | AP26: magia | AR26: altro | AT26: temp
Q27: Celestiale | V27: H | Z27: modificatori | AM27: + | AO27: + | AQ27: + | AS27: +
B28: H | Q28: Auran | V28: E | Y28: =
Q29: Gnomesco | U29: TAGLIA | Y29: =SUM(Y23,Y25,Y27,Y21) -> 1 | Z29: lottare | AC29: primaria | AE29: secondaria | AJ29: CA alla sprovvista | AK29: = | AL29: =AJ24-X7 -> 10 | AN29: CA contatto** | AO29: = | AP29: =AJ24-AN25-AP25-AL27 -> 13 | AR29: Fallimento incantesimi | AS29: = | AT29: =Equip!Z13+Equip!AA5 -> 0
B30: E | U30: MODIFICATORI
U31: maestria in comb
AI32: Note:
C33: TIRI SALVEZZA | R33: CONTANTI | X33: NOTE E APPUNTI | AI33: ** | AJ33: altro e magia inclusi. Se necessario vanno sottratti
R34: monete di platino
E35: totale | G35: base | I35: abilità | K35: magia | M35: altro
D36: Tempra | E36: =SUM(G36,I36,K36,M36)-AR7 -> 1 | F36: = | G36: 0 | H36: + | I36: =X9 -> 1 | J36: + | L36: + | R36: monete d'oro | T36: =80-15-5-1-2-1-8-1-1-1-1-32 -> 12 | AI36: Movimento
D38: Riflessi | E38: =SUM(G38,I38,K38,M38)-AR7 -> 3 | F38: = | G38: 0 | H38: + | I38: =X7 -> 3 | J38: + | L38: + | R38: monete d'argento | T38: =9-1-1-1 -> 6 | AJ38: Velocità di base: | AM38: 9 | AQ38: Volare: | AS38: 0
D40: Volontà | E40: =SUM(G40,I40,K40,M40)-AR7 -> 4 | F40: = | G40: 2 | H40: + | I40: =X13 -> 2 | J40: + | L40: + | R40: monete di rame | T40: =9 -> 9 | AJ40: Altro Movimento:
R41: DENARO PRESTATO, DEPOSITATO, RICEVUTO
R42: dove | T42: quando | V42: quanto | AJ42: MOVIMENTO | AM42: TATTICO (m/round) | AO42: LOCALE (m/minuto) | AQ42: ORA (km/ora) | AS42: GIORNO (km/8 ore)
AJ43: CAMMINARE | AM43: =IF(AS50="x",IF(AO50="x",AM40+AL48,AM40)&" m",IF(AS49="x",IF(AO49="x",AS38+AL48,AS38)&" m",IF(AO48="x",AM38+AL48,AM38)&" m")) -> 9 m | AO43: =IF(AS50="x",IF(AO50="x",(AM40+AL48)*10&" m",AM40*10&" m"), IF(AS49="x",IF(AO49="x",(AS38+AL48)*10&" m",AS38*10&" m"), IF(AO48="x",(AM38+AL48)*10&" m",AM38*10&" m"))) -> 90 m | AQ43: =IF(AS50="x",IF(AO50="x",(AM40+AL48)/2&" km",AM40/2&" km"), IF(AS49="x",IF(AO49="x",(AS38+AL48)/2&" km",AS38/2&" km"), IF(AO48="x",(AM38+AL48)/2&" km",AM38/2&" km"))) -> 4,5 km | AS43: =IF(AS50="x",IF(AO50="x",(AM40+AL48)*4&" km",AM40*4&" km"), IF(AS49="x",IF(AO49="x",(AS38+AL48)*4&" km",AS38*4&" km"), IF(AO48="x",(AM38+AL48)/2&" m",AM38*4&" km"))) -> 36 km
...

Sheet Equip
B2: ARMI MISCHIA | S2: ARMATURE
B3: Arma | D3: bonus a tc di arma | E3: incremento gittata | G3: critico | H3: danno totale | I3: taglia | J3: tipo | K3: Note | S3: Armature | U3: tipo | V3: Bonus CA | X3: Des max | Y3: penalità alla prova | AA3: fallimento incantesimi | AC3: velocità | AD3: peso | AE3: proprietà speciali | AG3: Note
B5: Bastone Ferrato | G5: x2 | H5: 1d6 | J5: c | P5: indossata
B7: Arco Corto | E7: 18m | G7: x3 | H7: 1d6 | J7: p
X9: inserire penalità negativa
S10: SCUDO
S11: Scudo | U11: taglia | V11: Bonus CA | X11: penalità alla prova | Z11: fallimento incantesimi | AB11: peso | AC11: proprietà speciali | AE11: Note
P13: indossata
B16: PROIETTILI | C16: TIPO | E16: quantità | H16: NOTE
C17: Freccia | E17: 39/40
S18: OGGETTO PROTETTIVO
S19: oggetto protettivo | U19: tipo | V19: Bonus CA | X19: Des max | Y19: penalità alla prova | AA19: fallimento incantesimi | AC19: velocità | AD19: peso | AE19: proprietà speciali | AG19: Note
B21: COMPENTENZA CON ARMI E ARMATURE
B22: ARMI | F22: ARMATURE | K22: NOTE
B23: Tutte le armi semplici | F23: armature leggere
B24: Tutte le armi da guerra | F24: armature medie
B25: da guerra | F25: armature pesante
B26: da guerra | F26: scudo
B27: esotica
B28: esotica

Sheet Capacità
B2: PRIVILEGI DI CLASSE | I2: CAPACITÀ MAGICHE | O2: DIVINITÀ E DOMINI | W2: EQUIPAGGIAMENTO
B3: Scuole Proibile: Necromanzia, Ammaliamento, Illusione | O3: Divinità: | W3: OGGETTI | Z3: I | AA3: Z | AB3: T | AC3: **
O4: Dominio: | W4: Libro Incantesimi (Vuoto) | AA4: x
O5: Poteri: | W5: Abito da studioso | Z5: x
W6: Borsa Componenti Incantesimi | Z6: x
W7: Giaciglio | AA7: x
O8: Dominio: | W8: Zaino | Z8: x
O9: Poteri: | W9: Gessetto | AA9: x
W10: Custodia Mappe o pergamene | AA10: x
W11: Inchiostro | AA11: x
O12: Dominio: | W12: Pennino | AA12: x
O13: Poteri: | W13: Otre | AA13: x
W14: Razione Viaggio (2) | AA14: x
W15: Foglio Pegamena (5) | AA15: x
O16: Dominio: | W16: Candela (10) | AA16: x
O17: Poteri: | W17: Acciarino | AA17: x
W18: Bastone Ferrato | Z18: x
W19: Arco Corto | Z19: x
O21: SCACCIARE NON MORTI | W21: Freccie (40) | Z21: x
O22: Prova: 1d20 + | R22: =Generali!X15 -> 2 | T22: RISULTATO | U22: MAX DV | W22: Corda | AA22: x
T23: Fino a 0 | U23: Liv. Chr -4 | W23: Lanterna | AA23: x
O24: DV influenzati | P24: 2d6 + liv | Q24: + | R24: =Generali!X15 -> 2 | T24: 1-3 | U24: Liv. Chr -3 | W24: Olio (2) | AA24: x
T25: 4-6 | U25: Liv. Chr -2 | W25: Pozione Rossa (2) | AA25: x
R26: talento | T26: 7-9 | U26: Liv. Chr -1
O27: Tentativi Giornalieri | P27: =3+Generali!X15+R27 -> 5 | Q27: + | T27: 10-12 | U27: Liv. Chr
T28: 13-15 | U28: Liv. Chr +1
T29: 16-18 | U29: Liv. Chr +2
O30: Note: | T30: 19-21 | U30: Liv. Chr +3
T31: 22+ | U31: Liv. Chr +4
O33: LEGENDA:
O34: I - indossati
O35: Z - Zaino
O36: T - Tasca da cintura
D38: Nome Elemento | E38: Quantità | F38: Costo Unitario (mo) | G38: Peso (kg) | H38: Incantesimo Associato | I38: Descrizione
D39: Filo di Ramme | E39: Focus | H39: Messaggio
D40: Pezzo cuoio conciato | E40: Focus | H40: Armatura Magica
D41: Ciuffo Pelo Cavallo | E41: 10 | H41: Cavalcatura
D42: Borsa Minuscola | E42: Focus | H42: Evoca Mostri
D43: Piccola Candela | E43: Focus | H43: Evoca Mostri
D44: Pezzo Spago | E44: 10 | H44: Servitore Inosservato
...

Sheet Incantesimi
C2: Incantesimi conosciuti: | P2: Incantesimi al giorno: | AB2: =IF(Generali!AR7>0, "HAI " & Generali!AR7 & " LIVELLI NEGATIVI! LEVATI " & Generali!AR7 & " SLOT DAL LIVELLO PIÙ ALTO", ":) Ci piace quando non ci sono livelli negativi eh") -> :) Ci piace quando non ci sono livelli negativi eh
B3: Liv. | C3: 0 | D3: 1 | E3: 2 | F3: 3 | G3: 4 | H3: 5 | I3: 6 | J3: 7 | K3: 8 | L3: 9 | O3: Liv. | P3: 0 | Q3: 1 | R3: 2 | S3: 3 | T3: 4 | U3: 5 | V3: 6 | W3: 7 | X3: 8 | Y3: 9
B4: N. | D4: 10 | O4: N. | P4: 2+3 | Q4: 1+3
N5: slot usati
B7: Liv. | C7: Livello 0 | F7: Man. | G7: Livello 1 | J7: Man. | K7: Livello 2 | N7: Man. | O7: Livello 3 | R7: Man. | S7: Livello 4 | V7: Man. | W7: Livello 5 | Z7: Man. | AA7: Livello 6 | AD7: Man. | AE7: Livello 7 | AH7: Man. | AI7: Livello 8 | AL7: Man. | AM7: Livello 9 | AP7: Man.
G8: Armatura Magica
G9: Cavalcatura
G10: Evoca Mostri I
G11: Servitore Inosservato
G12: Unto
G13: Globo di fuoco inferiore | J13: P. Ar
G14: Ripara Danni Leggeri ? | J14: P. Ar
G15: Scudo
G16: Ritirata Rapida
G17: Caduta Morbida
B19: Incantesimi preparati
C23: Livello 0 | F23: Livello 1 | I23: Livello 2 | L23: Livello 3 | O23: Livello 4 | R23: Livello 5 | U23: Livello 6 | X23: Livello 7 | AA23: Livello 8 | AD23: Livello 9
C24: Acid Splash | F24: Evoca Mostri I
C25: Mano Magica | F25: Evoca Mostri I
C26: Messaggio | F26: Scudo
C27: Resistenza | F27: Armatura Magica
C28: Read Magic
C36: Incantesimi conosciuti: | P36: Incantesimi al giorno:
B37: Liv. | C37: 0 | D37: 1 | E37: 2 | F37: 3 | G37: 4 | H37: 5 | I37: 6 | J37: 7 | K37: 8 | L37: 9 | O37: Liv. | P37: 0 | Q37: 1 | R37: 2 | S37: 3 | T37: 4 | U37: 5 | V37: 6 | W37: 7 | X37: 8 | Y37: 9
B38: N. | O38: N.
N39: slot usati
B41: Liv. | C41: Livello 0 | F41: Man. | G41: Livello 1 | J41: Man. | K41: Livello 2 | N41: Man. | O41: Livello 3 | R41: Man. | S41: Livello 4 | V41: Man. | W41: Livello 5 | Z41: Man. | AA41: Livello 6 | AD41: Man. | AE41: Livello 7 | AH41: Man. | AI41: Livello 8 | AL41: Man. | AM41: Livello 9 | AP41: Man.
B54: Incantesimi preparati
C58: Livello 0 | F58: Livello 1 | I58: Livello 2 | L58: Livello 3 | O58: Livello 4 | R58: Livello 5 | U58: Livello 6 | X58: Livello 7 | AA58: Livello 8 | AD58: Livello 9

Sheet Utility
A1: Livello | B1: Punti Esperienza Totali
A2: 1 | B2: 0
A3: 2 | B3: 1000
A4: 3 | B4: 3000
A5: 4 | B5: 6000
A6: 5 | B6: 10000
A7: 6 | B7: 15000
A8: 7 | B8: 21000
A9: 8 | B9: 28000
A10: 9 | B10: 36000
A11: 10 | B11: 45000
A12: 11 | B12: 55000
A13: 12 | B13: 66000
... A21: 20 | B21: 190000
